2023-11-08 17:58:34,182 ERROR: Exception on /reset_password/eyJhbGciOiJIUzI1NiIsInR5cCI6IkpXVCJ9.eyJyZXNldF9wYXNzd29yZCI6MSwiZXhwIjoxNjk5NDQxNjA3Ljg1OTAxMzh9.xRG6fBwoEi3p48_vQIj1pFQAaBH9xUeNAnG3VYq31Og [GET] [in /Users/panther13/Desktop/codespace/microBlog/venv/lib/python3.10/site-packages/flask/app.py:1414]
Traceback (most recent call last):
  File "/Users/panther13/Desktop/codespace/microBlog/venv/lib/python3.10/site-packages/flask/app.py", line 2190, in wsgi_app
    response = self.full_dispatch_request()
  File "/Users/panther13/Desktop/codespace/microBlog/venv/lib/python3.10/site-packages/flask/app.py", line 1486, in full_dispatch_request
    rv = self.handle_user_exception(e)
  File "/Users/panther13/Desktop/codespace/microBlog/venv/lib/python3.10/site-packages/flask/app.py", line 1484, in full_dispatch_request
    rv = self.dispatch_request()
  File "/Users/panther13/Desktop/codespace/microBlog/venv/lib/python3.10/site-packages/flask/app.py", line 1469, in dispatch_request
    return self.ensure_sync(self.view_functions[rule.endpoint])(**view_args)
  File "/Users/panther13/Desktop/codespace/microBlog/app/routes.py", line 114, in reset_password
    user = User.verify_reset_password_token(token)
AttributeError: type object 'User' has no attribute 'verify_reset_password_token'
2023-11-08 20:20:12,465 INFO: Microblog startup [in /Users/panther13/Desktop/codespace/microBlog/app/__init__.py:45]
2023-11-08 20:21:01,541 ERROR: Exception on /reset_password/eyJhbGciOiJIUzI1NiIsInR5cCI6IkpXVCJ9.eyJyZXNldF9wYXNzd29yZCI6MSwiZXhwIjoxNjk5NDUwMjQwLjAyNjIyN30.Gq2xDxin9qWMfXE7bTrBWMIE033LsuwUCuUWxvE_Di0 [GET] [in /Users/panther13/Desktop/codespace/microBlog/venv/lib/python3.10/site-packages/flask/app.py:1414]
Traceback (most recent call last):
  File "/Users/panther13/Desktop/codespace/microBlog/venv/lib/python3.10/site-packages/flask/app.py", line 2190, in wsgi_app
    response = self.full_dispatch_request()
  File "/Users/panther13/Desktop/codespace/microBlog/venv/lib/python3.10/site-packages/flask/app.py", line 1486, in full_dispatch_request
    rv = self.handle_user_exception(e)
  File "/Users/panther13/Desktop/codespace/microBlog/venv/lib/python3.10/site-packages/flask/app.py", line 1484, in full_dispatch_request
    rv = self.dispatch_request()
  File "/Users/panther13/Desktop/codespace/microBlog/venv/lib/python3.10/site-packages/flask/app.py", line 1469, in dispatch_request
    return self.ensure_sync(self.view_functions[rule.endpoint])(**view_args)
  File "/Users/panther13/Desktop/codespace/microBlog/app/routes.py", line 114, in reset_password
    user = User.verify_reset_password_token(token)
AttributeError: type object 'User' has no attribute 'verify_reset_password_token'
2023-11-08 21:18:06,544 ERROR: Exception on /reset_password/eyJhbGciOiJIUzI1NiIsInR5cCI6IkpXVCJ9.eyJyZXNldF9wYXNzd29yZCI6MSwiZXhwIjoxNjk5NDUwMjQwLjAyNjIyN30.Gq2xDxin9qWMfXE7bTrBWMIE033LsuwUCuUWxvE_Di0 [GET] [in /Users/panther13/Desktop/codespace/microBlog/venv/lib/python3.10/site-packages/flask/app.py:1414]
Traceback (most recent call last):
  File "/Users/panther13/Desktop/codespace/microBlog/venv/lib/python3.10/site-packages/flask/app.py", line 2190, in wsgi_app
    response = self.full_dispatch_request()
  File "/Users/panther13/Desktop/codespace/microBlog/venv/lib/python3.10/site-packages/flask/app.py", line 1486, in full_dispatch_request
    rv = self.handle_user_exception(e)
  File "/Users/panther13/Desktop/codespace/microBlog/venv/lib/python3.10/site-packages/flask/app.py", line 1484, in full_dispatch_request
    rv = self.dispatch_request()
  File "/Users/panther13/Desktop/codespace/microBlog/venv/lib/python3.10/site-packages/flask/app.py", line 1469, in dispatch_request
    return self.ensure_sync(self.view_functions[rule.endpoint])(**view_args)
  File "/Users/panther13/Desktop/codespace/microBlog/app/routes.py", line 114, in reset_password
    user = User.verify_reset_password_token(token)
AttributeError: type object 'User' has no attribute 'verify_reset_password_token'
2023-11-09 18:47:40,062 INFO: Microblog startup [in /Users/panther13/Desktop/codespace/microBlog/app/__init__.py:45]
2023-11-09 18:48:19,244 ERROR: Exception on /user/susan [GET] [in /Users/panther13/Desktop/codespace/microBlog/venv/lib/python3.10/site-packages/flask/app.py:1414]
Traceback (most recent call last):
  File "/Users/panther13/Desktop/codespace/microBlog/venv/lib/python3.10/site-packages/flask/app.py", line 2190, in wsgi_app
    response = self.full_dispatch_request()
  File "/Users/panther13/Desktop/codespace/microBlog/venv/lib/python3.10/site-packages/flask/app.py", line 1486, in full_dispatch_request
    rv = self.handle_user_exception(e)
  File "/Users/panther13/Desktop/codespace/microBlog/venv/lib/python3.10/site-packages/flask/app.py", line 1484, in full_dispatch_request
    rv = self.dispatch_request()
  File "/Users/panther13/Desktop/codespace/microBlog/venv/lib/python3.10/site-packages/flask/app.py", line 1469, in dispatch_request
    return self.ensure_sync(self.view_functions[rule.endpoint])(**view_args)
  File "/Users/panther13/Desktop/codespace/microBlog/venv/lib/python3.10/site-packages/flask_login/utils.py", line 290, in decorated_view
    return current_app.ensure_sync(func)(*args, **kwargs)
  File "/Users/panther13/Desktop/codespace/microBlog/app/routes.py", line 132, in user
    posts = user.posts.order_by(post.timestamp.desc()).paginate(
NameError: name 'post' is not defined
2023-11-09 18:51:42,795 ERROR: Exception on /user/susan [GET] [in /Users/panther13/Desktop/codespace/microBlog/venv/lib/python3.10/site-packages/flask/app.py:1414]
Traceback (most recent call last):
  File "/Users/panther13/Desktop/codespace/microBlog/venv/lib/python3.10/site-packages/flask/app.py", line 2190, in wsgi_app
    response = self.full_dispatch_request()
  File "/Users/panther13/Desktop/codespace/microBlog/venv/lib/python3.10/site-packages/flask/app.py", line 1486, in full_dispatch_request
    rv = self.handle_user_exception(e)
  File "/Users/panther13/Desktop/codespace/microBlog/venv/lib/python3.10/site-packages/flask/app.py", line 1484, in full_dispatch_request
    rv = self.dispatch_request()
  File "/Users/panther13/Desktop/codespace/microBlog/venv/lib/python3.10/site-packages/flask/app.py", line 1469, in dispatch_request
    return self.ensure_sync(self.view_functions[rule.endpoint])(**view_args)
  File "/Users/panther13/Desktop/codespace/microBlog/venv/lib/python3.10/site-packages/flask_login/utils.py", line 290, in decorated_view
    return current_app.ensure_sync(func)(*args, **kwargs)
  File "/Users/panther13/Desktop/codespace/microBlog/app/routes.py", line 132, in user
    posts = user.posts.order_by(post.timestamp.desc()).paginate(
NameError: name 'post' is not defined
2023-11-09 18:52:12,923 INFO: Microblog startup [in /Users/panther13/Desktop/codespace/microBlog/app/__init__.py:45]
2023-11-09 18:52:32,529 ERROR: Exception on /user/susan [GET] [in /Users/panther13/Desktop/codespace/microBlog/venv/lib/python3.10/site-packages/flask/app.py:1414]
Traceback (most recent call last):
  File "/Users/panther13/Desktop/codespace/microBlog/venv/lib/python3.10/site-packages/flask/app.py", line 2190, in wsgi_app
    response = self.full_dispatch_request()
  File "/Users/panther13/Desktop/codespace/microBlog/venv/lib/python3.10/site-packages/flask/app.py", line 1486, in full_dispatch_request
    rv = self.handle_user_exception(e)
  File "/Users/panther13/Desktop/codespace/microBlog/venv/lib/python3.10/site-packages/flask/app.py", line 1484, in full_dispatch_request
    rv = self.dispatch_request()
  File "/Users/panther13/Desktop/codespace/microBlog/venv/lib/python3.10/site-packages/flask/app.py", line 1469, in dispatch_request
    return self.ensure_sync(self.view_functions[rule.endpoint])(**view_args)
  File "/Users/panther13/Desktop/codespace/microBlog/venv/lib/python3.10/site-packages/flask_login/utils.py", line 290, in decorated_view
    return current_app.ensure_sync(func)(*args, **kwargs)
  File "/Users/panther13/Desktop/codespace/microBlog/app/routes.py", line 132, in user
    posts = user.posts.order_by(posts.timestamp.desc()).paginate(
UnboundLocalError: local variable 'posts' referenced before assignment
2023-11-09 18:53:47,126 INFO: Microblog startup [in /Users/panther13/Desktop/codespace/microBlog/app/__init__.py:45]
2023-11-09 18:54:04,555 ERROR: Exception on /user/susan [GET] [in /Users/panther13/Desktop/codespace/microBlog/venv/lib/python3.10/site-packages/flask/app.py:1414]
Traceback (most recent call last):
  File "/Users/panther13/Desktop/codespace/microBlog/venv/lib/python3.10/site-packages/flask/app.py", line 2190, in wsgi_app
    response = self.full_dispatch_request()
  File "/Users/panther13/Desktop/codespace/microBlog/venv/lib/python3.10/site-packages/flask/app.py", line 1486, in full_dispatch_request
    rv = self.handle_user_exception(e)
  File "/Users/panther13/Desktop/codespace/microBlog/venv/lib/python3.10/site-packages/flask/app.py", line 1484, in full_dispatch_request
    rv = self.dispatch_request()
  File "/Users/panther13/Desktop/codespace/microBlog/venv/lib/python3.10/site-packages/flask/app.py", line 1469, in dispatch_request
    return self.ensure_sync(self.view_functions[rule.endpoint])(**view_args)
  File "/Users/panther13/Desktop/codespace/microBlog/venv/lib/python3.10/site-packages/flask_login/utils.py", line 290, in decorated_view
    return current_app.ensure_sync(func)(*args, **kwargs)
  File "/Users/panther13/Desktop/codespace/microBlog/app/routes.py", line 132, in user
    posts = user.posts.order_by(Post.timestamp.desc()).paginate(
TypeError: Query.paginate() takes 1 positional argument but 4 were given
2023-11-09 18:55:09,389 INFO: Microblog startup [in /Users/panther13/Desktop/codespace/microBlog/app/__init__.py:45]
2023-11-09 18:55:25,700 INFO: Microblog startup [in /Users/panther13/Desktop/codespace/microBlog/app/__init__.py:45]
